<?xml version="1.0" encoding="utf-8"?>
<!-- This URDF was automatically created by SolidWorks to URDF Exporter! Originally created by Stephen Brawner (brawner@gmail.com) 
     Commit Version: 1.6.0-4-g7f85cfe  Build Version: 1.6.7995.38578
     For more information, please see http://wiki.ros.org/sw_urdf_exporter -->
<robot
  name="HiWonder LeArm.SLDASM">
  <link
    name="base_link">
    <inertial>
      <origin
        xyz="-0.43185 0.1296 0.27449"
        rpy="0 0 0" />
      <mass
        value="0.10816" />
      <inertia
        ixx="0.00066366"
        ixy="9.186E-06"
        ixz="8.755E-05"
        iyy="0.00084009"
        iyz="1.8788E-05"
        izz="0.00017932" />
    </inertial>
    <visual>
      <origin
        xyz="0 0 0"
        rpy="0 0 0" />
      <geometry>
        <mesh
          filename="package://HiWonder LeArm.SLDASM/meshes/base_link.STL" />
      </geometry>
      <material
        name="">
        <color
          rgba="0.19216 0.20392 0.20392 1" />
      </material>
    </visual>
    <collision>
      <origin
        xyz="0 0 0"
        rpy="0 0 0" />
      <geometry>
        <mesh
          filename="package://HiWonder LeArm.SLDASM/meshes/base_link.STL" />
      </geometry>
    </collision>
  </link>
  <link
    name="link_1">
    <inertial>
      <origin
        xyz="-5.1008E-05 0.0097186 0"
        rpy="0 0 0" />
      <mass
        value="0.0072429" />
      <inertia
        ixx="2.9208E-06"
        ixy="7.4761E-21"
        ixz="0"
        iyy="5.8773E-06"
        iyz="-3.6264E-21"
        izz="2.9592E-06" />
    </inertial>
    <visual>
      <origin
        xyz="0 0 0"
        rpy="0 0 0" />
      <geometry>
        <mesh
          filename="package://HiWonder LeArm.SLDASM/meshes/link_1.STL" />
      </geometry>
      <material
        name="">
        <color
          rgba="0.79216 0.81961 0.93333 1" />
      </material>
    </visual>
    <collision>
      <origin
        xyz="0 0 0"
        rpy="0 0 0" />
      <geometry>
        <mesh
          filename="package://HiWonder LeArm.SLDASM/meshes/link_1.STL" />
      </geometry>
    </collision>
  </link>
  <joint
    name="joint_1"
    type="revolute">
    <origin
      xyz="-0.43816 -0.33719 0.18851"
      rpy="1.5959 0.075451 -0.17097" />
    <parent
      link="base_link" />
    <child
      link="link_1" />
    <axis
      xyz="0 1 0" />
    <limit
      lower="-1.57"
      upper="1.57"
      effort="300"
      velocity="3" />
  </joint>
  <link
    name="link_2">
    <inertial>
      <origin
        xyz="0.0011306 -0.030437 7.4385E-15"
        rpy="0 0 0" />
      <mass
        value="0.0080412" />
      <inertia
        ixx="3.5873E-06"
        ixy="7.5935E-22"
        ixz="1.2705E-20"
        iyy="5.0884E-06"
        iyz="-1.5352E-21"
        izz="7.8121E-06" />
    </inertial>
    <visual>
      <origin
        xyz="0 0 0"
        rpy="0 0 0" />
      <geometry>
        <mesh
          filename="package://HiWonder LeArm.SLDASM/meshes/link_2.STL" />
      </geometry>
      <material
        name="">
        <color
          rgba="0.2 0.4 0.69804 1" />
      </material>
    </visual>
    <collision>
      <origin
        xyz="0 0 0"
        rpy="0 0 0" />
      <geometry>
        <mesh
          filename="package://HiWonder LeArm.SLDASM/meshes/link_2.STL" />
      </geometry>
    </collision>
  </link>
  <joint
    name="joint_2"
    type="revolute">
    <origin
      xyz="0 0.021569 0.009925"
      rpy="3.1416 0 0" />
    <parent
      link="link_1" />
    <child
      link="link_2" />
    <axis
      xyz="-1 0 0" />
    <limit
      lower="-1.05"
      upper="1.05"
      effort="300"
      velocity="3" />
  </joint>
  <link
    name="link_3">
    <inertial>
      <origin
        xyz="0.019926 0.0101 -0.02026"
        rpy="0 0 0" />
      <mass
        value="0.032733" />
      <inertia
        ixx="5.5941E-06"
        ixy="-2.9697E-13"
        ixz="1.4157E-10"
        iyy="8.8266E-06"
        iyz="2.6323E-14"
        izz="5.4334E-06" />
    </inertial>
    <visual>
      <origin
        xyz="0 0 0"
        rpy="0 0 0" />
      <geometry>
        <mesh
          filename="package://HiWonder LeArm.SLDASM/meshes/link_3.STL" />
      </geometry>
      <material
        name="">
        <color
          rgba="0.29804 0.29804 0.29804 1" />
      </material>
    </visual>
    <collision>
      <origin
        xyz="0 0 0"
        rpy="0 0 0" />
      <geometry>
        <mesh
          filename="package://HiWonder LeArm.SLDASM/meshes/link_3.STL" />
      </geometry>
    </collision>
  </link>
  <joint
    name="joint_3"
    type="revolute">
    <origin
      xyz="0.021181 -0.1141 0.01"
      rpy="-3.1406 1.5708 -3.1406" />
    <parent
      link="link_2" />
    <child
      link="link_3" />
    <axis
      xyz="0 0 0" />
    <limit
      lower="-3.14"
      upper="0"
      effort="300"
      velocity="3" />
  </joint>
  <link
    name="link_4">
    <inertial>
      <origin
        xyz="0.019622 0.010125 -0.020084"
        rpy="0 0 0" />
      <mass
        value="0.033951" />
      <inertia
        ixx="6.0856E-06"
        ixy="3.183E-21"
        ixz="-6.0918E-08"
        iyy="9.5842E-06"
        iyz="4.3013E-21"
        izz="5.7919E-06" />
    </inertial>
    <visual>
      <origin
        xyz="0 0 0"
        rpy="0 0 0" />
      <geometry>
        <mesh
          filename="package://HiWonder LeArm.SLDASM/meshes/link_4.STL" />
      </geometry>
      <material
        name="">
        <color
          rgba="0.79216 0.81961 0.93333 1" />
      </material>
    </visual>
    <collision>
      <origin
        xyz="0 0 0"
        rpy="0 0 0" />
      <geometry>
        <mesh
          filename="package://HiWonder LeArm.SLDASM/meshes/link_4.STL" />
      </geometry>
    </collision>
  </link>
  <joint
    name="joint_4"
    type="revolute">
    <origin
      xyz="0.0706 0.019975 -0.001575"
      rpy="1.5624 1.5708 -1.5799" />
    <parent
      link="link_3" />
    <child
      link="link_4" />
    <axis
      xyz="0 0 0" />
    <limit
      lower="-3.14"
      upper="0"
      effort="300"
      velocity="3" />
  </joint>
  <link
    name="link_5">
    <inertial>
      <origin
        xyz="-4.4409E-16 0.0016682 7.7716E-16"
        rpy="0 0 0" />
      <mass
        value="0.00088325" />
      <inertia
        ixx="2.3525E-08"
        ixy="-1.4631E-23"
        ixz="-7.6101E-23"
        iyy="4.5403E-08"
        iyz="4.3324E-23"
        izz="2.3525E-08" />
    </inertial>
    <visual>
      <origin
        xyz="0 0 0"
        rpy="0 0 0" />
      <geometry>
        <mesh
          filename="package://HiWonder LeArm.SLDASM/meshes/link_5.STL" />
      </geometry>
      <material
        name="">
        <color
          rgba="0.29804 0.29804 0.29804 1" />
      </material>
    </visual>
    <collision>
      <origin
        xyz="0 0 0"
        rpy="0 0 0" />
      <geometry>
        <mesh
          filename="package://HiWonder LeArm.SLDASM/meshes/link_5.STL" />
      </geometry>
    </collision>
  </link>
  <joint
    name="joint_5"
    type="revolute">
    <origin
      xyz="0.019862 -0.055112 -0.02935"
      rpy="0 0.7854 0" />
    <parent
      link="link_4" />
    <child
      link="link_5" />
    <axis
      xyz="0 0 0" />
    <limit
      lower="0"
      upper="3.14"
      effort="300"
      velocity="3" />
  </joint>
</robot>